Workbook

Sheet Derived Rates
A1: Irish Derived Cost Build-up — Spon's Civil Engineering Rates
A2: Cost of each item derived from Labour + Plant + Material (+ Sub-contract where the source publishes an all-in specialist rate), then converted to Irish costs in euro using the factors on the 'Irish Basis' sheet. IRISH COST € (column R) is the deliverable; UK COST £ (column M) is the build-up it derives from. Preliminaries / CESMM Class A General Items are excluded.
A4: Ref | B4: Page | C4: Class | D4: Section | E4: Sub-heading | F4: Item | G4: Unit | H4: Gang hrs | I4: Labour £ | J4: Plant £ | K4: Material £ | L4: Sub-contract £ | M4: UK COST £ | N4: Labour € | O4: Plant € | P4: Material € | Q4: Sub-contract € | R4: IRISH COST € | S4: Derivation basis | T4: Confidence | U4: Published rate £ (superseded) | V4: Variance £ | W4: Flag | X4: Derivation note
A5: 124 | B5: IMG_0066 | C5: CLASS B: GROUND INVESTIGATION | D5: 01 TRIAL PITS AND TRENCHES | E5: Trial holes measured by number; Excavating trial hole; plan size 1.0 x 2.0 m; supports, backfilling | F5: ne 1.0 m deep | G5: nr | H5: 0.24 | I5: 32.5 | J5: 89.59 | K5: 0 | L5: 0 | M5: =ROUND(SUM(I5:L5),2) | N5: =ROUND(I5*'Irish Basis'!$C$6*'Irish Basis'!$C$5,2) | O5: =ROUND(J5*'Irish Basis'!$C$7*'Irish Basis'!$C$5,2) | P5: =ROUND(K5*'Irish Basis'!$C$8*'Irish Basis'!$C$5,2) | Q5: =ROUND(L5*'Irish Basis'!$C$12*'Irish Basis'!$C$5,2) | R5: =ROUND(SUM(N5:Q5),2) | S5: Stated build-up | T5: High | U5: 122.09 | V5: =IF(U5="","",ROUND(M5-U5,2)) | X5: Labour + plant + material as published; reconciles to the published rate.
A6: 125 | B6: IMG_0066 | C6: CLASS B: GROUND INVESTIGATION | D6: 01 TRIAL PITS AND TRENCHES | E6: Trial holes measured by number; Excavating trial hole; plan size 1.0 x 2.0 m; supports, backfilling | F6: 1.0-2.0 m deep | G6: nr | H6: 0.47 | I6: 63.64 | J6: 114.75 | K6: 0 | L6: 0 | M6: =ROUND(SUM(I6:L6),2) | N6: =ROUND(I6*'Irish Basis'!$C$6*'Irish Basis'!$C$5,2) | O6: =ROUND(J6*'Irish Basis'!$C$7*'Irish Basis'!$C$5,2) | P6: =ROUND(K6*'Irish Basis'!$C$8*'Irish Basis'!$C$5,2) | Q6: =ROUND(L6*'Irish Basis'!$C$12*'Irish Basis'!$C$5,2) | R6: =ROUND(SUM(N6:Q6),2) | S6: Stated build-up | T6: High | U6: 178.4 | V6: =IF(U6="","",ROUND(M6-U6,2)) | X6: Labour + plant + material as published; reconciles to the published rate.
A7: 126 | B7: IMG_0066 | C7: CLASS B: GROUND INVESTIGATION | D7: 01 TRIAL PITS AND TRENCHES | E7: Trial holes measured by number; Excavating trial hole; plan size 1.0 x 2.0 m; supports, backfilling | F7: over 2.0 m deep | G7: nr | H7: 0.53 | I7: 71.77 | J7: 140.11 | K7: 0 | L7: 0 | M7: =ROUND(SUM(I7:L7),2) | N7: =ROUND(I7*'Irish Basis'!$C$6*'Irish Basis'!$C$5,2) | O7: =ROUND(J7*'Irish Basis'!$C$7*'Irish Basis'!$C$5,2) | P7: =ROUND(K7*'Irish Basis'!$C$8*'Irish Basis'!$C$5,2) | Q7: =ROUND(L7*'Irish Basis'!$C$12*'Irish Basis'!$C$5,2) | R7: =ROUND(SUM(N7:Q7),2) | S7: Stated build-up | T7: High | U7: 211.88 | V7: =IF(U7="","",ROUND(M7-U7,2)) | X7: Labour + plant + material as published; reconciles to the published rate.
A8: 128 | B8: IMG_0066 | C8: CLASS B: GROUND INVESTIGATION | D8: 01 TRIAL PITS AND TRENCHES | E8: Trial holes measured by number; Excavating trial hole in rock or similar; plan size 1.0 x 2.0 m; supports, backfilling | F8: ne 1.0 m deep | G8: nr | H8: 0.28 | I8: 37.92 | J8: 96.41 | K8: 0 | L8: 0 | M8: =ROUND(SUM(I8:L8),2) | N8: =ROUND(I8*'Irish Basis'!$C$6*'Irish Basis'!$C$5,2) | O8: =ROUND(J8*'Irish Basis'!$C$7*'Irish Basis'!$C$5,2) | P8: =ROUND(K8*'Irish Basis'!$C$8*'Irish Basis'!$C$5,2) | Q8: =ROUND(L8*'Irish Basis'!$C$12*'Irish Basis'!$C$5,2) | R8: =ROUND(SUM(N8:Q8),2) | S8: Stated build-up | T8: High | U8: 134.33 | V8: =IF(U8="","",ROUND(M8-U8,2)) | X8: Labour + plant + material as published; reconciles to the published rate.
A9: 129 | B9: IMG_0066 | C9: CLASS B: GROUND INVESTIGATION | D9: 01 TRIAL PITS AND TRENCHES | E9: Trial holes measured by number; Excavating trial hole in rock or similar; plan size 1.0 x 2.0 m; supports, backfilling | F9: 1.0-2.0 m deep | G9: nr | H9: 0.51 | I9: 69.06 | J9: 137.6 | K9: 0 | L9: 0 | M9: =ROUND(SUM(I9:L9),2) | N9: =ROUND(I9*'Irish Basis'!$C$6*'Irish Basis'!$C$5,2) | O9: =ROUND(J9*'Irish Basis'!$C$7*'Irish Basis'!$C$5,2) | P9: =ROUND(K9*'Irish Basis'!$C$8*'Irish Basis'!$C$5,2) | Q9: =ROUND(L9*'Irish Basis'!$C$12*'Irish Basis'!$C$5,2) | R9: =ROUND(SUM(N9:Q9),2) | S9: Stated build-up | T9: High | U9: 206.66 | V9: =IF(U9="","",ROUND(M9-U9,2)) | X9: Labour + plant + material as published; reconciles to the published rate.
A10: 130 | B10: IMG_0066 | C10: CLASS B: GROUND INVESTIGATION | D10: 01 TRIAL PITS AND TRENCHES | E10: Trial holes measured by number; Excavating trial hole in rock or similar; plan size 1.0 x 2.0 m; supports, backfilling | F10: over 2.0 m deep | G10: nr | H10: 0.58 | I10: 78.54 | J10: 164.71 | K10: 0 | L10: 0 | M10: =ROUND(SUM(I10:L10),2) | N10: =ROUND(I10*'Irish Basis'!$C$6*'Irish Basis'!$C$5,2) | O10: =ROUND(J10*'Irish Basis'!$C$7*'Irish Basis'!$C$5,2) | P10: =ROUND(K10*'Irish Basis'!$C$8*'Irish Basis'!$C$5,2) | Q10: =ROUND(L10*'Irish Basis'!$C$12*'Irish Basis'!$C$5,2) | R10: =ROUND(SUM(N10:Q10),2) | S10: Stated build-up | T10: High | U10: 243.25 | V10: =IF(U10="","",ROUND(M10-U10,2)) | X10: Labour + plant + material as published; reconciles to the published rate.
A11: 132 | B11: IMG_0066 | C11: CLASS B: GROUND INVESTIGATION | D11: 01 TRIAL PITS AND TRENCHES | E11: Trial holes measured by depth; Excavating trial hole; plan size 1.0 x 2.0 m; supports, backfilling | F11: ne 1.0 m deep | G11: m | H11: 0.24 | I11: 32.5 | J11: 91.39 | K11: 0 | L11: 0 | M11: =ROUND(SUM(I11:L11),2) | N11: =ROUND(I11*'Irish Basis'!$C$6*'Irish Basis'!$C$5,2) | O11: =ROUND(J11*'Irish Basis'!$C$7*'Irish Basis'!$C$5,2) | P11: =ROUND(K11*'Irish Basis'!$C$8*'Irish Basis'!$C$5,2) | Q11: =ROUND(L11*'Irish Basis'!$C$12*'Irish Basis'!$C$5,2) | R11: =ROUND(SUM(N11:Q11),2) | S11: Stated build-up | T11: High | U11: 123.89 | V11: =IF(U11="","",ROUND(M11-U11,2)) | X11: Labour + plant + material as published; reconciles to the published rate.
A12: 134 | B12: IMG_0067 | C12: CLASS B: GROUND INVESTIGATION | D12: 01 TRIAL PITS AND TRENCHES | E12: Trial holes measured by depth; Excavating trial hole; plan size 1.0 x 2.0 m; supports, backfilling (continued) | F12: 1.0-2.0 m deep | G12: m | H12: 0.53 | I12: 71.77 | J12: 127.86 | K12: 0 | L12: 0 | M12: =ROUND(SUM(I12:L12),2) | N12: =ROUND(I12*'Irish Basis'!$C$6*'Irish Basis'!$C$5,2) | O12: =ROUND(J12*'Irish Basis'!$C$7*'Irish Basis'!$C$5,2) | P12: =ROUND(K12*'Irish Basis'!$C$8*'Irish Basis'!$C$5,2) | Q12: =ROUND(L12*'Irish Basis'!$C$12*'Irish Basis'!$C$5,2) | R12: =ROUND(SUM(N12:Q12),2) | S12: Stated build-up | T12: High | U12: 199.63 | V12: =IF(U12="","",ROUND(M12-U12,2)) | X12: Labour + plant + material as published; reconciles to the published rate.
A13: 135 | B13: IMG_0067 | C13: CLASS B: GROUND INVESTIGATION | D13: 01 TRIAL PITS AND TRENCHES | E13: Trial holes measured by depth; Excavating trial hole; plan size 1.0 x 2.0 m; supports, backfilling (continued) | F13: 2.0-3.0 m deep | G13: m | H13: 0.59 | I13: 79.89 | J13: 135.29 | K13: 0 | L13: 0 | M13: =ROUND(SUM(I13:L13),2) | N13: =ROUND(I13*'Irish Basis'!$C$6*'Irish Basis'!$C$5,2) | O13: =ROUND(J13*'Irish Basis'!$C$7*'Irish Basis'!$C$5,2) | P13: =ROUND(K13*'Irish Basis'!$C$8*'Irish Basis'!$C$5,2) | Q13: =ROUND(L13*'Irish Basis'!$C$12*'Irish Basis'!$C$5,2) | R13: =ROUND(SUM(N13:Q13),2) | S13: Stated build-up | T13: High | U13: 215.18 | V13: =IF(U13="","",ROUND(M13-U13,2)) | X13: Labour + plant + material as published; reconciles to the published rate.
A14: 136 | B14: IMG_0067 | C14: CLASS B: GROUND INVESTIGATION | D14: 01 TRIAL PITS AND TRENCHES | E14: Trial holes measured by depth; Excavating trial hole; plan size 1.0 x 2.0 m; supports, backfilling (continued) | F14: 3.0-5.0 m deep | G14: m | H14: 0.65 | I14: 88.02 | J14: 179.68 | K14: 0 | L14: 0 | M14: =ROUND(SUM(I14:L14),2) | N14: =ROUND(I14*'Irish Basis'!$C$6*'Irish Basis'!$C$5,2) | O14: =ROUND(J14*'Irish Basis'!$C$7*'Irish Basis'!$C$5,2) | P14: =ROUND(K14*'Irish Basis'!$C$8*'Irish Basis'!$C$5,2) | Q14: =ROUND(L14*'Irish Basis'!$C$12*'Irish Basis'!$C$5,2) | R14: =ROUND(SUM(N14:Q14),2) | S14: Stated build-up | T14: High | U14: 267.7 | V14: =IF(U14="","",ROUND(M14-U14,2)) | X14: Labour + plant + material as published; reconciles to the published rate.
A15: 138 | B15: IMG_0067 | C15: CLASS B: GROUND INVESTIGATION | D15: 01 TRIAL PITS AND TRENCHES | E15: Excavating trial hole in rock or similar; plan size 1.0 x 2.0 m; supports, backfilling | F15: ne 1.0 m deep | G15: m | H15: 2.95 | I15: 399.47 | J15: 615.51 | K15: 0 | L15: 0 | M15: =ROUND(SUM(I15:L15),2) | N15: =ROUND(I15*'Irish Basis'!$C$6*'Irish Basis'!$C$5,2) | O15: =ROUND(J15*'Irish Basis'!$C$7*'Irish Basis'!$C$5,2) | P15: =ROUND(K15*'Irish Basis'!$C$8*'Irish Basis'!$C$5,2) | Q15: =ROUND(L15*'Irish Basis'!$C$12*'Irish Basis'!$C$5,2) | R15: =ROUND(SUM(N15:Q15),2) | S15: Stated build-up | T15: High | U15: 1014.98 | V15: =IF(U15="","",ROUND(M15-U15,2)) | X15: Labour + plant + material as published; reconciles to the published rate.
A16: 139 | B16: IMG_0067 | C16: CLASS B: GROUND INVESTIGATION | D16: 01 TRIAL PITS AND TRENCHES | E16: Excavating trial hole in rock or similar; plan size 1.0 x 2.0 m; supports, backfilling | F16: 1.0-2.0 m deep | G16: m | H16: 3.65 | I16: 494.26 | J16: 948.3 | K16: 0 | L16: 0 | M16: =ROUND(SUM(I16:L16),2) | N16: =ROUND(I16*'Irish Basis'!$C$6*'Irish Basis'!$C$5,2) | O16: =ROUND(J16*'Irish Basis'!$C$7*'Irish Basis'!$C$5,2) | P16: =ROUND(K16*'Irish Basis'!$C$8*'Irish Basis'!$C$5,2) | Q16: =ROUND(L16*'Irish Basis'!$C$12*'Irish Basis'!$C$5,2) | R16: =ROUND(SUM(N16:Q16),2) | S16: Stated build-up | T16: High | U16: 1442.56 | V16: =IF(U16="","",ROUND(M16-U16,2)) | X16: Labour + plant + material as published; reconciles to the published rate.
... A20: 144 | B20: IMG_0067 | C20: CLASS B: GROUND INVESTIGATION | D20: 01 TRIAL PITS AND TRENCHES | E20: Sundries in trial holes | F20: Pumping; maximum depth 4.0 m minimum 750 litres per hour | G20: hr | H20: 0.06 | I20: 3.18 | J20: 38.03 | K20: 0 | L20: 0 | M20: =ROUND(SUM(I20:L20),2) | N20: =ROUND(I20*'Irish Basis'!$C$6*'Irish Basis'!$C$5,2) | O20: =ROUND(J20*'Irish Basis'!$C$7*'Irish Basis'!$C$5,2) | P20: =ROUND(K20*'Irish Basis'!$C$8*'Irish Basis'!$C$5,2) | Q20: =ROUND(L20*'Irish Basis'!$C$12*'Irish Basis'!$C$5,2) | R20: =ROUND(SUM(N20:Q20),2) | S20: Stated build-up | T20: High | U20: 41.21 | V20: =IF(U20="","",ROUND(M20-U20,2)) | X20: Labour + plant + material as published; reconciles to the published rate.
A21: 148 | B21: IMG_0067 | C21: CLASS B: GROUND INVESTIGATION | D21: 02 LIGHT CABLE PERCUSSION BOREHOLES | E21: General | F21: Establishment of standard plant and equipment and removal on completion | G21: item | I21: 0 | J21: 0 | K21: 0 | L21: 16858.03 | M21: =ROUND(SUM(I21:L21),2) | N21: =ROUND(I21*'Irish Basis'!$C$6*'Irish Basis'!$C$5,2) | O21: =ROUND(J21*'Irish Basis'!$C$7*'Irish Basis'!$C$5,2) | P21: =ROUND(K21*'Irish Basis'!$C$8*'Irish Basis'!$C$5,2) | Q21: =ROUND(L21*'Irish Basis'!$C$12*'Irish Basis'!$C$5,2) | R21: =ROUND(SUM(N21:Q21),2) | S21: All-in specialist rate | T21: All-in (not split) | U21: 16858.03 | V21: =IF(U21="","",ROUND(M21-U21,2)) | X21: Source publishes a specialist/sub-contract all-in rate; no labour/plant/material build-up exists to derive from.
A22: 149 | B22: IMG_0067 | C22: CLASS B: GROUND INVESTIGATION | D22: 02 LIGHT CABLE PERCUSSION BOREHOLES | E22: General | F22: Number; 150 mm nominal dia. at base | G22: nr | I22: 0 | J22: 0 | K22: 0 | L22: 87.91 | M22: =ROUND(SUM(I22:L22),2) | N22: =ROUND(I22*'Irish Basis'!$C$6*'Irish Basis'!$C$5,2) | O22: =ROUND(J22*'Irish Basis'!$C$7*'Irish Basis'!$C$5,2) | P22: =ROUND(K22*'Irish Basis'!$C$8*'Irish Basis'!$C$5,2) | Q22: =ROUND(L22*'Irish Basis'!$C$12*'Irish Basis'!$C$5,2) | R22: =ROUND(SUM(N22:Q22),2) | S22: All-in specialist rate | T22: All-in (not split) | U22: 87.91 | V22: =IF(U22="","",ROUND(M22-U22,2)) | X22: Source publishes a specialist/sub-contract all-in rate; no labour/plant/material build-up exists to derive from.
A23: 151 | B23: IMG_0067 | C23: CLASS B: GROUND INVESTIGATION | D23: 02 LIGHT CABLE PERCUSSION BOREHOLES | E23: Depth; 150 mm nominal dia. of base | F23: in holes of maximum depth not exceeding 5 m | G23: m | I23: 0 | J23: 0 | K23: 0 | L23: 35.16 | M23: =ROUND(SUM(I23:L23),2) | N23: =ROUND(I23*'Irish Basis'!$C$6*'Irish Basis'!$C$5,2) | O23: =ROUND(J23*'Irish Basis'!$C$7*'Irish Basis'!$C$5,2) | P23: =ROUND(K23*'Irish Basis'!$C$8*'Irish Basis'!$C$5,2) | Q23: =ROUND(L23*'Irish Basis'!$C$12*'Irish Basis'!$C$5,2) | R23: =ROUND(SUM(N23:Q23),2) | S23: All-in specialist rate | T23: All-in (not split) | U23: 35.16 | V23: =IF(U23="","",ROUND(M23-U23,2)) | X23: Source publishes a specialist/sub-contract all-in rate; no labour/plant/material build-up exists to derive from.
A24: 152 | B24: IMG_0067 | C24: CLASS B: GROUND INVESTIGATION | D24: 02 LIGHT CABLE PERCUSSION BOREHOLES | E24: Depth; 150 mm nominal dia. of base | F24: in holes of maximum depth 5-10 m | G24: m | I24: 0 | J24: 0 | K24: 0 | L24: 35.16 | M24: =ROUND(SUM(I24:L24),2) | N24: =ROUND(I24*'Irish Basis'!$C$6*'Irish Basis'!$C$5,2) | O24: =ROUND(J24*'Irish Basis'!$C$7*'Irish Basis'!$C$5,2) | P24: =ROUND(K24*'Irish Basis'!$C$8*'Irish Basis'!$C$5,2) | Q24: =ROUND(L24*'Irish Basis'!$C$12*'Irish Basis'!$C$5,2) | R24: =ROUND(SUM(N24:Q24),2) | S24: All-in specialist rate | T24: All-in (not split) | U24: 35.16 | V24: =IF(U24="","",ROUND(M24-U24,2)) | X24: Source publishes a specialist/sub-contract all-in rate; no labour/plant/material build-up exists to derive from.
A25: 153 | B25: IMG_0067 | C25: CLASS B: GROUND INVESTIGATION | D25: 02 LIGHT CABLE PERCUSSION BOREHOLES | E25: Depth; 150 mm nominal dia. of base | F25: in holes of maximum depth 10-20 m | G25: m | I25: 0 | J25: 0 | K25: 0 | L25: 43.95 | M25: =ROUND(SUM(I25:L25),2) | N25: =ROUND(I25*'Irish Basis'!$C$6*'Irish Basis'!$C$5,2) | O25: =ROUND(J25*'Irish Basis'!$C$7*'Irish Basis'!$C$5,2) | P25: =ROUND(K25*'Irish Basis'!$C$8*'Irish Basis'!$C$5,2) | Q25: =ROUND(L25*'Irish Basis'!$C$12*'Irish Basis'!$C$5,2) | R25: =ROUND(SUM(N25:Q25),2) | S25: All-in specialist rate | T25: All-in (not split) | U25: 43.95 | V25: =IF(U25="","",ROUND(M25-U25,2)) | X25: Source publishes a specialist/sub-contract all-in rate; no labour/plant/material build-up exists to derive from.
A26: 154 | B26: IMG_0067 | C26: CLASS B: GROUND INVESTIGATION | D26: 02 LIGHT CABLE PERCUSSION BOREHOLES | E26: Depth; 150 mm nominal dia. of base | F26: in holes of maximum depth 20-30 m | G26: m | I26: 0 | J26: 0 | K26: 0 | L26: 56.24 | M26: =ROUND(SUM(I26:L26),2) | N26: =ROUND(I26*'Irish Basis'!$C$6*'Irish Basis'!$C$5,2) | O26: =ROUND(J26*'Irish Basis'!$C$7*'Irish Basis'!$C$5,2) | P26: =ROUND(K26*'Irish Basis'!$C$8*'Irish Basis'!$C$5,2) | Q26: =ROUND(L26*'Irish Basis'!$C$12*'Irish Basis'!$C$5,2) | R26: =ROUND(SUM(N26:Q26),2) | S26: All-in specialist rate | T26: All-in (not split) | U26: 56.24 | V26: =IF(U26="","",ROUND(M26-U26,2)) | X26: Source publishes a specialist/sub-contract all-in rate; no labour/plant/material build-up exists to derive from.
A27: 155 | B27: IMG_0067 | C27: CLASS B: GROUND INVESTIGATION | D27: 02 LIGHT CABLE PERCUSSION BOREHOLES | E27: Depth; 150 mm nominal dia. of base | F27: Depth backfilled; imported pulverised fuel ash | G27: m | I27: 0 | J27: 0 | K27: 0 | L27: 9.1 | M27: =ROUND(SUM(I27:L27),2) | N27: =ROUND(I27*'Irish Basis'!$C$6*'Irish Basis'!$C$5,2) | O27: =ROUND(J27*'Irish Basis'!$C$7*'Irish Basis'!$C$5,2) | P27: =ROUND(K27*'Irish Basis'!$C$8*'Irish Basis'!$C$5,2) | Q27: =ROUND(L27*'Irish Basis'!$C$12*'Irish Basis'!$C$5,2) | R27: =ROUND(SUM(N27:Q27),2) | S27: All-in specialist rate | T27: All-in (not split) | U27: 9.1 | V27: =IF(U27="","",ROUND(M27-U27,2)) | X27: Source publishes a specialist/sub-contract all-in rate; no labour/plant/material build-up exists to derive from.
A28: 156 | B28: IMG_0067 | C28: CLASS B: GROUND INVESTIGATION | D28: 02 LIGHT CABLE PERCUSSION BOREHOLES | E28: Depth; 150 mm nominal dia. of base | F28: Depth backfilled; imported gravel | G28: m | I28: 0 | J28: 0 | K28: 0 | L28: 12.73 | M28: =ROUND(SUM(I28:L28),2) | N28: =ROUND(I28*'Irish Basis'!$C$6*'Irish Basis'!$C$5,2) | O28: =ROUND(J28*'Irish Basis'!$C$7*'Irish Basis'!$C$5,2) | P28: =ROUND(K28*'Irish Basis'!$C$8*'Irish Basis'!$C$5,2) | Q28: =ROUND(L28*'Irish Basis'!$C$12*'Irish Basis'!$C$5,2) | R28: =ROUND(SUM(N28:Q28),2) | S28: All-in specialist rate | T28: All-in (not split) | U28: 12.73 | V28: =IF(U28="","",ROUND(M28-U28,2)) | X28: Source publishes a specialist/sub-contract all-in rate; no labour/plant/material build-up exists to derive from.
A29: 157 | B29: IMG_0067 | C29: CLASS B: GROUND INVESTIGATION | D29: 02 LIGHT CABLE PERCUSSION BOREHOLES | E29: Depth; 150 mm nominal dia. of base | F29: Depth backfilled; bentonite grout | G29: m | I29: 0 | J29: 0 | K29: 0 | L29: 18.21 | M29: =ROUND(SUM(I29:L29),2) | N29: =ROUND(I29*'Irish Basis'!$C$6*'Irish Basis'!$C$5,2) | O29: =ROUND(J29*'Irish Basis'!$C$7*'Irish Basis'!$C$5,2) | P29: =ROUND(K29*'Irish Basis'!$C$8*'Irish Basis'!$C$5,2) | Q29: =ROUND(L29*'Irish Basis'!$C$12*'Irish Basis'!$C$5,2) | R29: =ROUND(SUM(N29:Q29),2) | S29: All-in specialist rate | T29: All-in (not split) | U29: 18.21 | V29: =IF(U29="","",ROUND(M29-U29,2)) | X29: Source publishes a specialist/sub-contract all-in rate; no labour/plant/material build-up exists to derive from.
A30: 158 | B30: IMG_0067 | C30: CLASS B: GROUND INVESTIGATION | D30: 02 LIGHT CABLE PERCUSSION BOREHOLES | E30: Depth; 150 mm nominal dia. of base | F30: Chiselling to prove rock or to penetrate obstructions | G30: hour | I30: 0 | J30: 0 | K30: 0 | L30: 87.93 | M30: =ROUND(SUM(I30:L30),2) | N30: =ROUND(I30*'Irish Basis'!$C$6*'Irish Basis'!$C$5,2) | O30: =ROUND(J30*'Irish Basis'!$C$7*'Irish Basis'!$C$5,2) | P30: =ROUND(K30*'Irish Basis'!$C$8*'Irish Basis'!$C$5,2) | Q30: =ROUND(L30*'Irish Basis'!$C$12*'Irish Basis'!$C$5,2) | R30: =ROUND(SUM(N30:Q30),2) | S30: All-in specialist rate | T30: All-in (not split) | U30: 87.93 | V30: =IF(U30="","",ROUND(M30-U30,2)) | X30: Source publishes a specialist/sub-contract all-in rate; no labour/plant/material build-up exists to derive from.
A31: 159 | B31: IMG_0067 | C31: CLASS B: GROUND INVESTIGATION | D31: 02 LIGHT CABLE PERCUSSION BOREHOLES | E31: Depth; 150 mm nominal dia. of base | F31: Standing time of rig and crew | G31: hour | I31: 0 | J31: 0 | K31: 0 | L31: 87.93 | M31: =ROUND(SUM(I31:L31),2) | N31: =ROUND(I31*'Irish Basis'!$C$6*'Irish Basis'!$C$5,2) | O31: =ROUND(J31*'Irish Basis'!$C$7*'Irish Basis'!$C$5,2) | P31: =ROUND(K31*'Irish Basis'!$C$8*'Irish Basis'!$C$5,2) | Q31: =ROUND(L31*'Irish Basis'!$C$12*'Irish Basis'!$C$5,2) | R31: =ROUND(SUM(N31:Q31),2) | S31: All-in specialist rate | T31: All-in (not split) | U31: 87.93 | V31: =IF(U31="","",ROUND(M31-U31,2)) | X31: Source publishes a specialist/sub-contract all-in rate; no labour/plant/material build-up exists to derive from.
A32: 162 | B32: IMG_0067 | C32: CLASS B: GROUND INVESTIGATION | D32: 03 ROTARY DRILLED BOREHOLES | F32: Establishment of standard plant and equipment and removal on completion | G32: item | I32: 0 | J32: 0 | K32: 0 | L32: 42145.07 | M32: =ROUND(SUM(I32:L32),2) | N32: =ROUND(I32*'Irish Basis'!$C$6*'Irish Basis'!$C$5,2) | O32: =ROUND(J32*'Irish Basis'!$C$7*'Irish Basis'!$C$5,2) | P32: =ROUND(K32*'Irish Basis'!$C$8*'Irish Basis'!$C$5,2) | Q32: =ROUND(L32*'Irish Basis'!$C$12*'Irish Basis'!$C$5,2) | R32: =ROUND(SUM(N32:Q32),2) | S32: All-in specialist rate | T32: All-in (not split) | U32: 42145.07 | V32: =IF(U32="","",ROUND(M32-U32,2)) | X32: Source publishes a specialist/sub-contract all-in rate; no labour/plant/material build-up exists to derive from.
A33: 163 | B33: IMG_0067 | C33: CLASS B: GROUND INVESTIGATION | D33: 03 ROTARY DRILLED BOREHOLES | F33: Setting up at each borehole position | G33: nr | I33: 0 | J33: 0 | K33: 0 | L33: 17.58 | M33: =ROUND(SUM(I33:L33),2) | N33: =ROUND(I33*'Irish Basis'!$C$6*'Irish Basis'!$C$5,2) | O33: =ROUND(J33*'Irish Basis'!$C$7*'Irish Basis'!$C$5,2) | P33: =ROUND(K33*'Irish Basis'!$C$8*'Irish Basis'!$C$5,2) | Q33: =ROUND(L33*'Irish Basis'!$C$12*'Irish Basis'!$C$5,2) | R33: =ROUND(SUM(N33:Q33),2) | S33: All-in specialist rate | T33: All-in (not split) | U33: 17.58 | V33: =IF(U33="","",ROUND(M33-U33,2)) | X33: Source publishes a specialist/sub-contract all-in rate; no labour/plant/material build-up exists to derive from.
A34: 165 | B34: IMG_0067 | C34: CLASS B: GROUND INVESTIGATION | D34: 03 ROTARY DRILLED BOREHOLES | E34: Depth without core recovery; nominal minimum core dia. 100 mm | F34: ne 5.0 m deep | G34: m | I34: 0 | J34: 0 | K34: 0 | L34: 99.82 | M34: =ROUND(SUM(I34:L34),2) | N34: =ROUND(I34*'Irish Basis'!$C$6*'Irish Basis'!$C$5,2) | O34: =ROUND(J34*'Irish Basis'!$C$7*'Irish Basis'!$C$5,2) | P34: =ROUND(K34*'Irish Basis'!$C$8*'Irish Basis'!$C$5,2) | Q34: =ROUND(L34*'Irish Basis'!$C$12*'Irish Basis'!$C$5,2) | R34: =ROUND(SUM(N34:Q34),2) | S34: All-in specialist rate | T34: All-in (not split) | U34: 99.82 | V34: =IF(U34="","",ROUND(M34-U34,2)) | X34: Source publishes a specialist/sub-contract all-in rate; no labour/plant/material build-up exists to derive from.
A35: 166 | B35: IMG_0067 | C35: CLASS B: GROUND INVESTIGATION | D35: 03 ROTARY DRILLED BOREHOLES | E35: Depth without core recovery; nominal minimum core dia. 100 mm | F35: 5-10 m deep | G35: m | I35: 0 | J35: 0 | K35: 0 | L35: 99.82 | M35: =ROUND(SUM(I35:L35),2) | N35: =ROUND(I35*'Irish Basis'!$C$6*'Irish Basis'!$C$5,2) | O35: =ROUND(J35*'Irish Basis'!$C$7*'Irish Basis'!$C$5,2) | P35: =ROUND(K35*'Irish Basis'!$C$8*'Irish Basis'!$C$5,2) | Q35: =ROUND(L35*'Irish Basis'!$C$12*'Irish Basis'!$C$5,2) | R35: =ROUND(SUM(N35:Q35),2) | S35: All-in specialist rate | T35: All-in (not split) | U35: 99.82 | V35: =IF(U35="","",ROUND(M35-U35,2)) | X35: Source publishes a specialist/sub-contract all-in rate; no labour/plant/material build-up exists to derive from.
A36: 167 | B36: IMG_0067 | C36: CLASS B: GROUND INVESTIGATION | D36: 03 ROTARY DRILLED BOREHOLES | E36: Depth without core recovery; nominal minimum core dia. 100 mm | F36: 10-20 m deep | G36: m | I36: 0 | J36: 0 | K36: 0 | L36: 110.47 | M36: =ROUND(SUM(I36:L36),2) | N36: =ROUND(I36*'Irish Basis'!$C$6*'Irish Basis'!$C$5,2) | O36: =ROUND(J36*'Irish Basis'!$C$7*'Irish Basis'!$C$5,2) | P36: =ROUND(K36*'Irish Basis'!$C$8*'Irish Basis'!$C$5,2) | Q36: =ROUND(L36*'Irish Basis'!$C$12*'Irish Basis'!$C$5,2) | R36: =ROUND(SUM(N36:Q36),2) | S36: All-in specialist rate | T36: All-in (not split) | U36: 110.47 | V36: =IF(U36="","",ROUND(M36-U36,2)) | X36: Source publishes a specialist/sub-contract all-in rate; no labour/plant/material build-up exists to derive from.
A37: 168 | B37: IMG_0067 | C37: CLASS B: GROUND INVESTIGATION | D37: 03 ROTARY DRILLED BOREHOLES | E37: Depth without core recovery; nominal minimum core dia. 100 mm | F37: 20-30 m deep | G37: m | I37: 0 | J37: 0 | K37: 0 | L37: 110.47 | M37: =ROUND(SUM(I37:L37),2) | N37: =ROUND(I37*'Irish Basis'!$C$6*'Irish Basis'!$C$5,2) | O37: =ROUND(J37*'Irish Basis'!$C$7*'Irish Basis'!$C$5,2) | P37: =ROUND(K37*'Irish Basis'!$C$8*'Irish Basis'!$C$5,2) | Q37: =ROUND(L37*'Irish Basis'!$C$12*'Irish Basis'!$C$5,2) | R37: =ROUND(SUM(N37:Q37),2) | S37: All-in specialist rate | T37: All-in (not split) | U37: 110.47 | V37: =IF(U37="","",ROUND(M37-U37,2)) | X37: Source publishes a specialist/sub-contract all-in rate; no labour/plant/material build-up exists to derive from.
A38: 170 | B38: IMG_0067 | C38: CLASS B: GROUND INVESTIGATION | D38: 03 ROTARY DRILLED BOREHOLES | E38: Depth with core recovery; nominal minimum core dia. 75 mm | F38: ne 5.0 m deep | G38: m | I38: 0 | J38: 0 | K38: 0 | L38: 163.71 | M38: =ROUND(SUM(I38:L38),2) | N38: =ROUND(I38*'Irish Basis'!$C$6*'Irish Basis'!$C$5,2) | O38: =ROUND(J38*'Irish Basis'!$C$7*'Irish Basis'!$C$5,2) | P38: =ROUND(K38*'Irish Basis'!$C$8*'Irish Basis'!$C$5,2) | Q38: =ROUND(L38*'Irish Basis'!$C$12*'Irish Basis'!$C$5,2) | R38: =ROUND(SUM(N38:Q38),2) | S38: All-in specialist rate | T38: All-in (not split) | U38: 163.71 | V38: =IF(U38="","",ROUND(M38-U38,2)) | X38: Source publishes a specialist/sub-contract all-in rate; no labour/plant/material build-up exists to derive from.
A39: 171 | B39: IMG_0067 | C39: CLASS B: GROUND INVESTIGATION | D39: 03 ROTARY DRILLED BOREHOLES | E39: Depth with core recovery; nominal minimum core dia. 75 mm | F39: 5-10 m deep | G39: m | I39: 0 | J39: 0 | K39: 0 | L39: 165.04 | M39: =ROUND(SUM(I39:L39),2) | N39: =ROUND(I39*'Irish Basis'!$C$6*'Irish Basis'!$C$5,2) | O39: =ROUND(J39*'Irish Basis'!$C$7*'Irish Basis'!$C$5,2) | P39: =ROUND(K39*'Irish Basis'!$C$8*'Irish Basis'!$C$5,2) | Q39: =ROUND(L39*'Irish Basis'!$C$12*'Irish Basis'!$C$5,2) | R39: =ROUND(SUM(N39:Q39),2) | S39: All-in specialist rate | T39: All-in (not split) | U39: 165.04 | V39: =IF(U39="","",ROUND(M39-U39,2)) | X39: Source publishes a specialist/sub-contract all-in rate; no labour/plant/material build-up exists to derive from.
A40: 172 | B40: IMG_0067 | C40: CLASS B: GROUND INVESTIGATION | D40: 03 ROTARY DRILLED BOREHOLES | E40: Depth with core recovery; nominal minimum core dia. 75 mm | F40: 10-20 m deep | G40: m | I40: 0 | J40: 0 | K40: 0 | L40: 192.99 | M40: =ROUND(SUM(I40:L40),2) | N40: =ROUND(I40*'Irish Basis'!$C$6*'Irish Basis'!$C$5,2) | O40: =ROUND(J40*'Irish Basis'!$C$7*'Irish Basis'!$C$5,2) | P40: =ROUND(K40*'Irish Basis'!$C$8*'Irish Basis'!$C$5,2) | Q40: =ROUND(L40*'Irish Basis'!$C$12*'Irish Basis'!$C$5,2) | R40: =ROUND(SUM(N40:Q40),2) | S40: All-in specialist rate | T40: All-in (not split) | U40: 192.99 | V40: =IF(U40="","",ROUND(M40-U40,2)) | X40: Source publishes a specialist/sub-contract all-in rate; no labour/plant/material build-up exists to derive from.
A41: 173 | B41: IMG_0067 | C41: CLASS B: GROUND INVESTIGATION | D41: 03 ROTARY DRILLED BOREHOLES | E41: Depth with core recovery; nominal minimum core dia. 75 mm | F41: 20-30 m deep | G41: m | I41: 0 | J41: 0 | K41: 0 | L41: 263.53 | M41: =ROUND(SUM(I41:L41),2) | N41: =ROUND(I41*'Irish Basis'!$C$6*'Irish Basis'!$C$5,2) | O41: =ROUND(J41*'Irish Basis'!$C$7*'Irish Basis'!$C$5,2) | P41: =ROUND(K41*'Irish Basis'!$C$8*'Irish Basis'!$C$5,2) | Q41: =ROUND(L41*'Irish Basis'!$C$12*'Irish Basis'!$C$5,2) | R41: =ROUND(SUM(N41:Q41),2) | S41: All-in specialist rate | T41: All-in (not split) | U41: 263.53 | V41: =IF(U41="","",ROUND(M41-U41,2)) | X41: Source publishes a specialist/sub-contract all-in rate; no labour/plant/material build-up exists to derive from.
A42: 174 | B42: IMG_0067 | C42: CLASS B: GROUND INVESTIGATION | D42: 03 ROTARY DRILLED BOREHOLES | E42: Depth with core recovery; nominal minimum core dia. 75 mm | F42: Depth cased; semi-rigid plastic core barrel liner | G42: m | I42: 0 | J42: 0 | K42: 0 | L42: 15.97 | M42: =ROUND(SUM(I42:L42),2) | N42: =ROUND(I42*'Irish Basis'!$C$6*'Irish Basis'!$C$5,2) | O42: =ROUND(J42*'Irish Basis'!$C$7*'Irish Basis'!$C$5,2) | P42: =ROUND(K42*'Irish Basis'!$C$8*'Irish Basis'!$C$5,2) | Q42: =ROUND(L42*'Irish Basis'!$C$12*'Irish Basis'!$C$5,2) | R42: =ROUND(SUM(N42:Q42),2) | S42: All-in specialist rate | T42: All-in (not split) | U42: 15.97 | V42: =IF(U42="","",ROUND(M42-U42,2)) | X42: Source publishes a specialist/sub-contract all-in rate; no labour/plant/material build-up exists to derive from.
A43: 177 | B43: IMG_0067 | C43: CLASS B: GROUND INVESTIGATION | D43: 04 SAMPLES | E43: General; From the surface or from trial pits and trenches | F43: undisturbed soft material; minimum 200 mm cube | G43: nr | I43: 0 | J43: 0 | K43: 0 | L43: 28.59 | M43: =ROUND(SUM(I43:L43),2) | N43: =ROUND(I43*'Irish Basis'!$C$6*'Irish Basis'!$C$5,2) | O43: =ROUND(J43*'Irish Basis'!$C$7*'Irish Basis'!$C$5,2) | P43: =ROUND(K43*'Irish Basis'!$C$8*'Irish Basis'!$C$5,2) | Q43: =ROUND(L43*'Irish Basis'!$C$12*'Irish Basis'!$C$5,2) | R43: =ROUND(SUM(N43:Q43),2) | S43: All-in specialist rate | T43: All-in (not split) | U43: 28.59 | V43: =IF(U43="","",ROUND(M43-U43,2)) | X43: Source publishes a specialist/sub-contract all-in rate; no labour/plant/material build-up exists to derive from.
A44: 178 | B44: IMG_0067 | C44: CLASS B: GROUND INVESTIGATION | D44: 04 SAMPLES | E44: General; From the surface or from trial pits and trenches | F44: disturbed soft material; minimum 5 kg | G44: nr | I44: 0 | J44: 0 | K44: 0 | L44: 4.48 | M44: =ROUND(SUM(I44:L44),2) | N44: =ROUND(I44*'Irish Basis'!$C$6*'Irish Basis'!$C$5,2) | O44: =ROUND(J44*'Irish Basis'!$C$7*'Irish Basis'!$C$5,2) | P44: =ROUND(K44*'Irish Basis'!$C$8*'Irish Basis'!$C$5,2) | Q44: =ROUND(L44*'Irish Basis'!$C$12*'Irish Basis'!$C$5,2) | R44: =ROUND(SUM(N44:Q44),2) | S44: All-in specialist rate | T44: All-in (not split) | U44: 4.48 | V44: =IF(U44="","",ROUND(M44-U44,2)) | X44: Source publishes a specialist/sub-contract all-in rate; no labour/plant/material build-up exists to derive from.
...

Sheet Irish Basis
B1: Irish Basis — conversion inputs
B2: Every rate on 'Derived Rates' is converted to euro from these cells. Change one and all 3,793 items re-cost.
B4: Conversion inputs — edit the yellow cells
B5: GBP → EUR exchange rate | C5: 1.1694 | H5: Spot rate, August 2026. The 2026 year-to-date average is 1.1562 — use that instead for a budget or a fixed-price tender.
B6: Labour factor (Ireland ÷ UK) | C6: =G19 | H6: Calculated from the grade comparison below, so it follows the exchange rate. Overwrite with your own number if you have better evidence.
B7: Plant factor (Ireland ÷ UK) | C7: 1 | H7: ASSUMPTION — set to parity. No published Ireland-vs-UK plant differential was found. Plant is internationally traded capital equipment and the two hire markets share the same major suppliers. This is the weakest input here; override it if you have hire-desk quotes.
B8: Material factor (Ireland ÷ UK) | C8: 1 | H8: ASSUMPTION — set to parity. No published Ireland-vs-UK price-LEVEL series exists (Eurostat's construction PLIs dropped the UK after Brexit). Irish material inflation is running below the UK (3.2% vs 6.0% y/y to June 2026), so the gap is narrowing, not widening. Override with your own supplier data.
B9: Sub-contract mix — labour share | C9: 0.35 | H9: The assumed make-up of a specialist sub-contract package. Specialist trades (piling, tunnelling, demolition) are more labour and plant intensive than the book average.
B10: Sub-contract mix — plant share | C10: 0.3
B11: Sub-contract mix — material share | C11: 0.35
B12: Sub-contract factor (calculated) | C12: =ROUND(C9*C6+C10*C7+C11*C8,4) | H12: Blended from the three factors above using that mix. Applies to the 653 items carried as all-in specialist rates.
B14: How the labour factor was derived
B15: Irish grade (SEO) | C15: Ireland €/hr | D15: UK equivalent (CIJC) | E15: UK £/hr | F15: UK €/hr | G15: Ratio
B16: Craftsperson | C16: 23.74 | D16: Craft rate | E16: 16.4 | F16: =ROUND(E16*$C$5,2) | G16: =ROUND(C16/F16,4)
B17: Category A (skilled operative) | C17: 23.03 | D17: Skill Rate 3 | E17: 14.07 | F17: =ROUND(E17*$C$5,2) | G17: =ROUND(C17/F17,4)
B18: Category B (general operative) | C18: 21.37 | D18: General operative | E18: 13.18 | F18: =ROUND(E18*$C$5,2) | G18: =ROUND(C18/F18,4)
B19: Blended (equal weight) | G19: =ROUND(AVERAGE(G16:G18),4) | H19: Irish statutory construction rates run about a third above the UK equivalents once converted to euro. These are BASIC rates: employer on-costs differ too (UK NI 15% vs Irish PRSI ~11.25%), which would trim the premium slightly. Refine with your own all-in rates if you have them.
B21: Evidence behind each factor
B22: Labour | C22: Strong — statutory rates both sides, current, like-for-like grades | H22: Ireland: Sectoral Employment Order (Construction), rates effective 1 August 2026. UK: CIJC Working Rule Agreement, rates effective 20 July 2026.
B23: Exchange rate | C23: Strong — observable market rate | H23: GBP/EUR spot, August 2026 (~1.1694); 2026 year-to-date average 1.1562.
B24: Plant | C24: Weak — assumption, no source found | H24: No published Ireland-vs-UK plant hire differential located. Consumer hire-price guides for the two markets are not like-for-like on machine size.
B25: Material | C25: Weak — assumption, no source found | H25: No Ireland-vs-UK price-LEVEL series exists post-Brexit. Inflation RATES are available and diverging (CSO Ireland 3.2%, UK 6.0% y/y to June 2026) but rates of change cannot establish a level difference.
B26: Cross-check | C26: Top-down sanity check | H26: Arcadis International Construction Costs 2025 ranks Dublin 9th globally and Bristol 8th, with London 2nd — so overall Irish construction cost sits close to a major UK regional city, below London. A labour-led premium with materials near parity is consistent with that.
B28: Sources
B29: • | C29: Sectoral Employment Order (Construction Sector), Ireland — rates from 1 Aug 2026: Craftsperson €23.74, Category A €23.03, Category B €21.37, New Entrant €17.28.
B30: • | C30: CIJC Working Rule Agreement, UK — rates from 20 Jul 2026: Craft £16.40, Skill Rate 3 £14.07, General Operative £13.18.
B31: • | C31: GBP/EUR exchange rate, August 2026 — spot ~1.1694, 2026 YTD average 1.1562.
B32: • | C32: CSO Ireland Wholesale Price Index (building and construction materials) and UK building materials index — 3.2% vs 6.0% year-on-year to June 2026.
B33: • | C33: Arcadis International Construction Costs 2025 — Dublin 9th, Bristol 8th, London 2nd of 100 locations.
B34: • | C34: SCSI Tender Price Index, February 2026 — Irish commercial construction inflation 3% in H1 2026.

Sheet Review Queue
A1: Review Queue — items needing a human check
A2: 131 of 3793 derived items. These are carried in 'Derived Rates' at the values shown; review before relying on them.
A4: Ref | B4: Page | C4: Class | D4: Section | E4: Sub-heading | F4: Item | G4: Unit | H4: Gang hrs | I4: Labour £ | J4: Plant £ | K4: Material £ | L4: Sub-contract £ | M4: UK COST £ | N4: Labour € | O4: Plant € | P4: Material € | Q4: Sub-contract € | R4: IRISH COST € | S4: Derivation basis | T4: Confidence | U4: Published rate £ (superseded) | V4: Variance £ | W4: Flag | X4: Derivation note
A5: 319 | B5: IMG_0069 | C5: CLASS C: GEOTECHNICAL AND OTHER SPECIALIST PROCESSES | D5: 05 DIAPHRAGM WALLS | F5: Establishment of standard plant and equipment including bentonite storage tanks and removal on completion | G5: item | I5: 0 | J5: 0 | K5: 0 | L5: 549099.11 | M5: 549099.11 | N5: 0 | O5: 0 | P5: 0 | Q5: 718843 | R5: 718843 | S5: All-in specialist rate | T5: All-in (not split) | U5: 549099.11 | V5: 0 | W5: Probable source error — verify | X5: Source publishes a specialist/sub-contract all-in rate; no labour/plant/material build-up exists to derive from. This is 28x the next highest item in the class (£19,700.58) and out of line with comparable rates in the same section — likely a mis-read digit in the source scan. Verify before use.
A6: 370 | B6: IMG_0070 | C6: CLASS C: GEOTECHNICAL AND OTHER SPECIALIST PROCESSES | D6: 08 VIBRO-FLOTATION AND DYNAMIC COMPACTION | E6: Vibro flotation | F6: Depth not exceeding 5 m | G6: m | H6: 0.6 | I6: 19.07 | J6: 56.33 | K6: 0 | L6: 2436.35 | M6: 2511.75 | N6: 29.91 | O6: 65.87 | P6: 0 | Q6: 3189.5 | R6: 3285.29 | S6: Stated components + specialist balance | T6: Medium | U6: 2511.75 | V6: 0 | W6: Large unexplained balance | X6: Published plant/labour retained; the £2,436.35 balance of the specialist all-in rate is not broken down in the source.
A7: 371 | B7: IMG_0070 | C7: CLASS C: GEOTECHNICAL AND OTHER SPECIALIST PROCESSES | D7: 08 VIBRO-FLOTATION AND DYNAMIC COMPACTION | E7: Vibro flotation | F7: Depth: 5 m-10 m | G7: m | H7: 1.5 | I7: 47.69 | J7: 29.8 | K7: 0 | L7: 3070.38 | M7: 3147.87 | N7: 74.81 | O7: 34.85 | P7: 0 | Q7: 4019.53 | R7: 4129.19 | S7: Stated components + specialist balance | T7: Medium | U7: 3147.87 | V7: 0 | W7: Large unexplained balance | X7: Published plant/labour retained; the £3,070.38 balance of the specialist all-in rate is not broken down in the source.
A8: 372 | B8: IMG_0070 | C8: CLASS C: GEOTECHNICAL AND OTHER SPECIALIST PROCESSES | D8: 08 VIBRO-FLOTATION AND DYNAMIC COMPACTION | E8: Vibro flotation | F8: Depth: 10 m-20 m | G8: m | H8: 1.5 | I8: 47.69 | J8: 53.89 | K8: 0 | L8: 4283.89 | M8: 4385.47 | N8: 74.81 | O8: 63.02 | P8: 0 | Q8: 5608.18 | R8: 5746 | S8: Stated components + specialist balance | T8: Medium | U8: 4385.47 | V8: 0 | W8: Large unexplained balance | X8: Published plant/labour retained; the £4,283.89 balance of the specialist all-in rate is not broken down in the source.
A9: 373 | B9: IMG_0070 | C9: CLASS C: GEOTECHNICAL AND OTHER SPECIALIST PROCESSES | D9: 08 VIBRO-FLOTATION AND DYNAMIC COMPACTION | E9: Vibro flotation | F9: Depth: 30 m-40 m | G9: m | H9: 3 | I9: 95.37 | J9: 59.59 | K9: 0 | L9: 6924.55 | M9: 7079.51 | N9: 149.6 | O9: 69.68 | P9: 0 | Q9: 9065.15 | R9: 9284.43 | S9: Stated components + specialist balance | T9: Medium | U9: 7079.51 | V9: 0 | W9: Large unexplained balance | X9: Published plant/labour retained; the £6,924.55 balance of the specialist all-in rate is not broken down in the source.
A10: 589 | B10: IMG_0073 | C10: CLASS E: EARTHWORKS | D10: 01 EXCAVATION BY DREDGING | E10: In tidal locations, creating new channels on approaches to quays and similar locations or within dock systems | F10: approximate daily cost of backhoe dredger and two hopper barges £12,500; average production 100 m3/hr, 1,500 m3/day; locate, load, deposit and relocate | G10: m3 | I10: 4.13 | J10: 8.71 | K10: 0 | L10: 0 | M10: 12.84 | N10: 6.48 | O10: 10.19 | P10: 0 | Q10: 0 | R10: 16.66 | S10: Apportioned (class) | T10: Low | U10: 12.84 | V10: 0 | W10: Apportioned at class level | X10: Split from published rate using median L/P/M shares of 306 comparable build-ups at class level (32/68/0).
A11: 592 | B11: IMG_0073 | C11: CLASS E: EARTHWORKS | D11: 01 EXCAVATION BY DREDGING | E11: For general bed lowering or in maintaining shipping channels in rivers, estuaries or deltas | F11: locate, load, deposit and relocate | G11: tonne | I11: 1.67 | J11: 3.53 | K11: 0 | L11: 0 | M11: 5.2 | N11: 2.62 | O11: 4.13 | P11: 0 | Q11: 0 | R11: 6.75 | S11: Apportioned (class) | T11: Low | U11: 5.2 | V11: 0 | W11: Apportioned at class level | X11: Split from published rate using median L/P/M shares of 306 comparable build-ups at class level (32/68/0).
A12: 595 | B12: IMG_0073 | C12: CLASS E: EARTHWORKS | D12: 01 EXCAVATION BY DREDGING | E12: Harbour bed control | F12: average pumping capacity of silt/sand type materials containing maximum 30% volume of solids would be about 8,000 m3/day based on 24 hour working. Daily cost (hire basis) in the region of £20,000 including all floating equipment and discharge pipes, maintenance and all labour and plant to service but excluding mobilization/ initial set-up and demobilization costs (minimum £10,000). | G12: m3 | I12: 1.54 | J12: 3.25 | K12: 0 | L12: 0 | M12: 4.79 | N12: 2.42 | O12: 3.8 | P12: 0 | Q12: 0 | R12: 6.22 | S12: Apportioned (class) | T12: Low | U12: 4.79 | V12: 0 | W12: Apportioned at class level | X12: Split from published rate using median L/P/M shares of 306 comparable build-ups at class level (32/68/0).
A13: 598 | B13: IMG_0073 | C13: CLASS E: EARTHWORKS | D13: 01 EXCAVATION BY DREDGING | E13: For use in lakes, canals, rivers, industrial lagoons and from silted locations in dock systems | F13: average pumping output 30 m3 per hour and approximate average costs (excluding mobilization and demobilization costs ranging between £3,000 and £6,000 apiece) | G13: m3 | I13: 2.84 | J13: 5.97 | K13: 0 | L13: 0 | M13: 8.81 | N13: 4.45 | O13: 6.98 | P13: 0 | Q13: 0 | R13: 11.44 | S13: Apportioned (class) | T13: Low | U13: 8.81 | V13: 0 | W13: Apportioned at class level | X13: Split from published rate using median L/P/M shares of 306 comparable build-ups at class level (32/68/0).
A14: 1713 | B14: IMG_0090 | C14: CLASS H: PRECAST CONCRETE | D14: 02 PRESTRESSED PRE-TENSIONED BEAMS | E14: Bridge beams; Inverted 'T' Beams, flange width 495 mm | F14: section T1; 8 m long, 380 mm deep; mass 1.88t | G14: nr | I14: 845.93 | J14: 0 | K14: 974.65 | L14: 0 | M14: 1820.58 | N14: 1326.95 | O14: 0 | P14: 1139.76 | Q14: 0 | R14: 2466.71 | S14: Apportioned (class) | T14: Low | U14: 1820.58 | V14: 0 | W14: Apportioned at class level | X14: Split from published rate using median L/P/M shares of 19 comparable build-ups at class level (46/0/54).
A15: 1714 | B15: IMG_0090 | C15: CLASS H: PRECAST CONCRETE | D15: 02 PRESTRESSED PRE-TENSIONED BEAMS | E15: Bridge beams; Inverted 'T' Beams, flange width 495 mm | F15: section T2; 9 m long, 420 mm deep; mass 2.29t | G15: nr | I15: 1042.66 | J15: 0 | K15: 1201.3 | L15: 0 | M15: 2243.96 | N15: 1635.55 | O15: 0 | P15: 1404.8 | Q15: 0 | R15: 3040.35 | S15: Apportioned (class) | T15: Low | U15: 2243.96 | V15: 0 | W15: Apportioned at class level | X15: Split from published rate using median L/P/M shares of 19 comparable build-ups at class level (46/0/54).
A16: 1715 | B16: IMG_0090 | C16: CLASS H: PRECAST CONCRETE | D16: 02 PRESTRESSED PRE-TENSIONED BEAMS | E16: Bridge beams; Inverted 'T' Beams, flange width 495 mm | F16: section T3; 11 m long, 535 mm deep; mass 3.02t | G16: nr | I16: 1229.55 | J16: 0 | K16: 1416.63 | L16: 0 | M16: 2646.18 | N16: 1928.71 | O16: 0 | P16: 1656.61 | Q16: 0 | R16: 3585.32 | S16: Apportioned (class) | T16: Low | U16: 2646.18 | V16: 0 | W16: Apportioned at class level | X16: Split from published rate using median L/P/M shares of 19 comparable build-ups at class level (46/0/54).
A17: 1716 | B17: IMG_0090 | C17: CLASS H: PRECAST CONCRETE | D17: 02 PRESTRESSED PRE-TENSIONED BEAMS | E17: Bridge beams; Inverted 'T' Beams, flange width 495 mm | F17: section T4; 12 m long, 575 mm deep; mass 3.54t | G17: nr | I17: 1278.74 | J17: 0 | K17: 1473.31 | L17: 0 | M17: 2752.05 | N17: 2005.87 | O17: 0 | P17: 1722.89 | Q17: 0 | R17: 3728.76 | S17: Apportioned (class) | T17: Low | U17: 2752.05 | V17: 0 | W17: Apportioned at class level | X17: Split from published rate using median L/P/M shares of 19 comparable build-ups at class level (46/0/54).
A18: 1717 | B18: IMG_0090 | C18: CLASS H: PRECAST CONCRETE | D18: 02 PRESTRESSED PRE-TENSIONED BEAMS | E18: Bridge beams; Inverted 'T' Beams, flange width 495 mm | F18: section T5; 13 m long, 615 mm deep; mass 4.08t | G18: nr | I18: 1426.28 | J18: 0 | K18: 1643.3 | L18: 0 | M18: 3069.58 | N18: 2237.31 | O18: 0 | P18: 1921.68 | Q18: 0 | R18: 4158.99 | S18: Apportioned (class) | T18: Low | U18: 3069.58 | V18: 0 | W18: Apportioned at class level | X18: Split from published rate using median L/P/M shares of 19 comparable build-ups at class level (46/0/54).
A19: 1718 | B19: IMG_0090 | C19: CLASS H: PRECAST CONCRETE | D19: 02 PRESTRESSED PRE-TENSIONED BEAMS | E19: Bridge beams; Inverted 'T' Beams, flange width 495 mm | F19: section T6; 13 m long, 655 mm deep; mass 4.33t | G19: nr | I19: 1426.29 | J19: 0 | K19: 1643.31 | L19: 0 | M19: 3069.6 | N19: 2237.33 | O19: 0 | P19: 1921.69 | Q19: 0 | R19: 4159.01 | S19: Apportioned (class) | T19: Low | U19: 3069.6 | V19: 0 | W19: Apportioned at class level | X19: Split from published rate using median L/P/M shares of 19 comparable build-ups at class level (46/0/54).
A20: 1719 | B20: IMG_0090 | C20: CLASS H: PRECAST CONCRETE | D20: 02 PRESTRESSED PRE-TENSIONED BEAMS | E20: Bridge beams; Inverted 'T' Beams, flange width 495 mm | F20: section T7; 14 m long, 695 mm deep; mass 4.95t | G20: nr | I20: 1524.65 | J20: 0 | K20: 1756.64 | L20: 0 | M20: 3281.29 | N20: 2391.62 | O20: 0 | P20: 2054.21 | Q20: 0 | R20: 4445.83 | S20: Apportioned (class) | T20: Low | U20: 3281.29 | V20: 0 | W20: Apportioned at class level | X20: Split from published rate using median L/P/M shares of 19 comparable build-ups at class level (46/0/54).
A21: 1720 | B21: IMG_0090 | C21: CLASS H: PRECAST CONCRETE | D21: 02 PRESTRESSED PRE-TENSIONED BEAMS | E21: Bridge beams; Inverted 'T' Beams, flange width 495 mm | F21: section T8; 15 m long, 735 mm deep; mass 5.60t | G21: nr | I21: 1721.38 | J21: 0 | K21: 1983.29 | L21: 0 | M21: 3704.67 | N21: 2700.21 | O21: 0 | P21: 2319.26 | Q21: 0 | R21: 5019.47 | S21: Apportioned (class) | T21: Low | U21: 3704.67 | V21: 0 | W21: Apportioned at class level | X21: Split from published rate using median L/P/M shares of 19 comparable build-ups at class level (46/0/54).
... A124: 4431 | B124: IMG_0125 | C124: CLASS Q: PILING ANCILLARIES | D124: 08 PILE TESTS | E124: Pile tests; 430 mm dia. working pile; maximum test load of 1125kN using non-working tension piles as reaction; subsequent piles | F124: Make cure and test concrete cubes | G124: nr | I124: 0 | J124: 0 | K124: 0 | L124: 15.94 | M124: 15.94 | N124: 0 | O124: 0 | P124: 0 | Q124: 20.87 | R124: 20.87 | S124: All-in specialist rate | T124: All-in (not split) | U124: 15.94 | V124: 0 | W124: Outlier vs comparable items | X124: Source publishes a specialist/sub-contract all-in rate; no labour/plant/material build-up exists to derive from. Derived cost is far from the median of comparable items in this group (£1,170.81) — check the source figure.
A125: 4883 | B125: IMG_0131 | C125: CLASS R: ROADS AND PAVINGS | D125: 08 ANCILLARIES | E125: Standard reflectorized traffic signs | F125: extra for fixing singly to one face only | G125: nr | H125: 0.01 | I125: 1.14 | J125: 0.63 | K125: 0 | L125: 0 | M125: 1.77 | N125: 1.79 | O125: 0.74 | P125: 0 | Q125: 0 | R125: 2.52 | S125: Stated build-up | T125: High | U125: 1.78 | V125: -0.01 | W125: Outlier vs comparable items | X125: Labour + plant + material as published; reconciles to the published rate. Derived cost is far from the median of comparable items in this group (£71.87) — check the source figure.
A126: 4891 | B126: IMG_0131 | C126: CLASS R: ROADS AND PAVINGS | D126: 08 ANCILLARIES | E126: Standard two post signs; 1200 x 400 mm | F126: extra for fixing singly to one face only | G126: nr | H126: 0.02 | I126: 2.28 | J126: 1.32 | K126: 0 | L126: 0 | M126: 3.6 | N126: 3.58 | O126: 1.54 | P126: 0 | Q126: 0 | R126: 5.12 | S126: Stated build-up | T126: High | U126: 3.6 | V126: 0 | W126: Outlier vs comparable items | X126: Labour + plant + material as published; reconciles to the published rate. Derived cost is far from the median of comparable items in this group (£175.15) — check the source figure.
A127: 5252 | B127: IMG_0137 | C127: CLASS T: TUNNELS | D127: 03 IN SITU LINING TO SHAFTS | E127: Constructed in situ concrete | F127: Provision of complete standard shaft in in situ concrete; including piling, walls, floors, roof, drainage, finishes etc. | G127: nr | I127: 0 | J127: 0 | K127: 0 | L127: 50182994 | M127: 50182994 | N127: 0 | O127: 0 | P127: 0 | Q127: 65696143 | R127: 65696143 | S127: All-in specialist rate | T127: All-in (not split) | U127: 50182994 | V127: 0 | W127: Probable source error — verify | X127: Source publishes a specialist/sub-contract all-in rate; no labour/plant/material build-up exists to derive from. This is 20x the next highest item in the class (£2,534,723.45) and out of line with comparable rates in the same section — likely a mis-read digit in the source scan. Verify before use.
A128: 5266 | B128: IMG_0137 | C128: CLASS T: TUNNELS | D128: 03 IN SITU LINING TO SHAFTS | E128: Depressurization allowances | F128: Depressurization measures allowances | G128: nr | I128: 0 | J128: 0 | K128: 0 | L128: 752744.9 | M128: 752744.9 | N128: 0 | O128: 0 | P128: 0 | Q128: 985442.14 | R128: 985442.14 | S128: All-in specialist rate | T128: All-in (not split) | U128: 752744.9 | V128: 0 | W128: High value — verify | X128: Source publishes a specialist/sub-contract all-in rate; no labour/plant/material build-up exists to derive from. Unit rate of £250,000 or more — plausible for major specialist works but worth verifying against the source.
A129: 5339 | B129: IMG_0138 | C129: CLASS T: TUNNELS | D129: 09 VIADUCTS | E129: Permanent casings each length | F129: In situ Reinforced Concrete Piers on piles; off shore standard vertical pier | G129: nr | I129: 0 | J129: 0 | K129: 0 | L129: 646688.97 | M129: 646688.97 | N129: 0 | O129: 0 | P129: 0 | Q129: 846600.97 | R129: 846600.97 | S129: All-in specialist rate | T129: All-in (not split) | U129: 646688.97 | V129: 0 | W129: High value — verify | X129: Source publishes a specialist/sub-contract all-in rate; no labour/plant/material build-up exists to derive from. Unit rate of £250,000 or more — plausible for major specialist works but worth verifying against the source.
A130: 5340 | B130: IMG_0138 | C130: CLASS T: TUNNELS | D130: 09 VIADUCTS | E130: Permanent casings each length | F130: V shaped pier | G130: nr | I130: 0 | J130: 0 | K130: 0 | L130: 2534723.5 | M130: 2534723.5 | N130: 0 | O130: 0 | P130: 0 | Q130: 3318286.6 | R130: 3318286.6 | S130: All-in specialist rate | T130: All-in (not split) | U130: 2534723.5 | V130: 0 | W130: High value — verify | X130: Source publishes a specialist/sub-contract all-in rate; no labour/plant/material build-up exists to derive from. Unit rate of £250,000 or more — plausible for major specialist works but worth verifying against the source.
A131: 5341 | B131: IMG_0138 | C131: CLASS T: TUNNELS | D131: 09 VIADUCTS | E131: Permanent casings each length | F131: fixed buttress 3 legs pier | G131: nr | I131: 0 | J131: 0 | K131: 0 | L131: 1189313.1 | M131: 1189313.1 | N131: 0 | O131: 0 | P131: 0 | Q131: 1556967.3 | R131: 1556967.3 | S131: All-in specialist rate | T131: All-in (not split) | U131: 1189313.1 | V131: 0 | W131: High value — verify | X131: Source publishes a specialist/sub-contract all-in rate; no labour/plant/material build-up exists to derive from. Unit rate of £250,000 or more — plausible for major specialist works but worth verifying against the source.
A132: 5343 | B132: IMG_0138 | C132: CLASS T: TUNNELS | D132: 09 VIADUCTS | E132: In situ Reinforced Concrete Piers on piles; on shore | F132: standard vertical pier | G132: nr | I132: 0 | J132: 0 | K132: 0 | L132: 624389.35 | M132: 624389.35 | N132: 0 | O132: 0 | P132: 0 | Q132: 817407.83 | R132: 817407.83 | S132: All-in specialist rate | T132: All-in (not split) | U132: 624389.35 | V132: 0 | W132: High value — verify | X132: Source publishes a specialist/sub-contract all-in rate; no labour/plant/material build-up exists to derive from. Unit rate of £250,000 or more — plausible for major specialist works but worth verifying against the source.
A133: 5344 | B133: IMG_0138 | C133: CLASS T: TUNNELS | D133: 09 VIADUCTS | E133: In situ Reinforced Concrete Piers on piles; on shore | F133: fixed vertical pier | G133: nr | I133: 0 | J133: 0 | K133: 0 | L133: 1273456.9 | M133: 1273456.9 | N133: 0 | O133: 0 | P133: 0 | Q133: 1667122.7 | R133: 1667122.7 | S133: All-in specialist rate | T133: All-in (not split) | U133: 1273456.9 | V133: 0 | W133: High value — verify | X133: Source publishes a specialist/sub-contract all-in rate; no labour/plant/material build-up exists to derive from. Unit rate of £250,000 or more — plausible for major specialist works but worth verifying against the source.
A134: 5345 | B134: IMG_0138 | C134: CLASS T: TUNNELS | D134: 09 VIADUCTS | E134: In situ Reinforced Concrete Piers on piles; on shore | F134: expansion buttress pier | G134: nr | I134: 0 | J134: 0 | K134: 0 | L134: 859362.22 | M134: 859362.22 | N134: 0 | O134: 0 | P134: 0 | Q134: 1125018.2 | R134: 1125018.2 | S134: All-in specialist rate | T134: All-in (not split) | U134: 859362.22 | V134: 0 | W134: High value — verify | X134: Source publishes a specialist/sub-contract all-in rate; no labour/plant/material build-up exists to derive from. Unit rate of £250,000 or more — plausible for major specialist works but worth verifying against the source.
A135: 5346 | B135: IMG_0138 | C135: CLASS T: TUNNELS | D135: 09 VIADUCTS | E135: In situ Reinforced Concrete Piers on piles; on shore | F135: fixed buttress 3 legs pier | G135: nr | I135: 0 | J135: 0 | K135: 0 | L135: 1184853.1 | M135: 1184853.1 | N135: 0 | O135: 0 | P135: 0 | Q135: 1551128.7 | R135: 1551128.7 | S135: All-in specialist rate | T135: All-in (not split) | U135: 1184853.1 | V135: 0 | W135: High value — verify | X135: Source publishes a specialist/sub-contract all-in rate; no labour/plant/material build-up exists to derive from. Unit rate of £250,000 or more — plausible for major specialist works but worth verifying against the source.

Sheet Resource Rates
A1: Resource Rates — labour gang and plant build-ups
A2: The hourly labour-gang and plant rates published in the source. These are cost INPUTS, not priceable items, and are excluded from 'Derived Rates'. Rows reading 'Total Gang Rate/Hour' or 'Total Rate/Hour' are the composite rates.
A4: Ref | B4: Page | C4: Class | D4: Resource type | E4: Gang / plant spread | F4: Resource | G4: Labour £/hr | H4: Plant £/hr | I4: Material £
A5: 107 | B5: IMG_0066 | C5: CLASS B: GROUND INVESTIGATION | D5: RESOURCES - LABOUR | E5: Labour Gang Build-up Rate; Trial hole gang | F5: 1 ganger or chargehand (skill rate 4) | G5: 31.39
A6: 108 | B6: IMG_0066 | C6: CLASS B: GROUND INVESTIGATION | D6: RESOURCES - LABOUR | E6: Labour Gang Build-up Rate; Trial hole gang | F6: 1 skilled operative (skill rate 4) | G6: 29.49
A7: 109 | B7: IMG_0066 | C7: CLASS B: GROUND INVESTIGATION | D7: RESOURCES - LABOUR | E7: Labour Gang Build-up Rate; Trial hole gang | F7: 2 unskilled operatives (general) | G7: 49.35
A8: 110 | B8: IMG_0066 | C8: CLASS B: GROUND INVESTIGATION | D8: RESOURCES - LABOUR | E8: Labour Gang Build-up Rate; Trial hole gang | F8: 1 plant operator (skill rate 3) | G8: 38.96
A9: 111 | B9: IMG_0066 | C9: CLASS B: GROUND INVESTIGATION | D9: RESOURCES - LABOUR | E9: Labour Gang Build-up Rate; Trial hole gang | F9: Total Gang Rate/Hour | G9: 135.41
A10: 114 | B10: IMG_0066 | C10: CLASS B: GROUND INVESTIGATION | D10: RESOURCES - PLANT | E10: Plant Resources Build-up Rate; Trial holes | F10: 8 tonne wheeled backacter | H10: 72.4
A11: 115 | B11: IMG_0066 | C11: CLASS B: GROUND INVESTIGATION | D11: RESOURCES - PLANT | E11: Plant Resources Build-up Rate; Trial holes | F11: 3 tonne dumper | H11: 21.07
A12: 116 | B12: IMG_0066 | C12: CLASS B: GROUND INVESTIGATION | D12: RESOURCES - PLANT | E12: Plant Resources Build-up Rate; Trial holes | F12: 3.7 m3/min compressor, 2 tool | H12: 21.22
A13: 117 | B13: IMG_0066 | C13: CLASS B: GROUND INVESTIGATION | D13: RESOURCES - PLANT | E13: Plant Resources Build-up Rate; Trial holes | F13: two 2.4 m3/min road breakers | H13: 16.6
A14: 118 | B14: IMG_0066 | C14: CLASS B: GROUND INVESTIGATION | D14: RESOURCES - PLANT | E14: Plant Resources Build-up Rate; Trial holes | F14: extra 50 ft / 15 m hose | H14: 0.53
A15: 119 | B15: IMG_0066 | C15: CLASS B: GROUND INVESTIGATION | D15: RESOURCES - PLANT | E15: Plant Resources Build-up Rate; Trial holes | F15: plate compactors; vibrating compaction; plate 180 kg/ 600 mm | H15: 4.92
A16: 120 | B16: IMG_0066 | C16: CLASS B: GROUND INVESTIGATION | D16: RESOURCES - PLANT | E16: Plant Resources Build-up Rate; Trial holes | F16: Total Rate/Hour | H16: 136.73
A17: 527 | B17: IMG_0072 | C17: CLASS E: EARTHWORKS | D17: RESOURCES - LABOUR | E17: Labour Gang Build-up Rates; Excavation for cuttings gang | F17: 1 plant operator (skill rate 1) - 33% of time | G17: 17.5
A18: 528 | B18: IMG_0072 | C18: CLASS E: EARTHWORKS | D18: RESOURCES - LABOUR | E18: Labour Gang Build-up Rates; Excavation for cuttings gang | F18: 1 plant operator (skill rate 2) - 66% of time | G18: 29.63
A19: 529 | B19: IMG_0072 | C19: CLASS E: EARTHWORKS | D19: RESOURCES - LABOUR | E19: Labour Gang Build-up Rates; Excavation for cuttings gang | F19: 1 banksman (skill rate 4) | G19: 29.49
A20: 530 | B20: IMG_0072 | C20: CLASS E: EARTHWORKS | D20: RESOURCES - LABOUR | E20: Labour Gang Build-up Rates; Excavation for cuttings gang | F20: Total Gang Rate/Hour | G20: 73.78
A21: 532 | B21: IMG_0072 | C21: CLASS E: EARTHWORKS | D21: RESOURCES - LABOUR | E21: Excavation for foundations gang | F21: 1 plant operator (skill rate 3) - 33% of time | G21: 12.86
A22: 533 | B22: IMG_0072 | C22: CLASS E: EARTHWORKS | D22: RESOURCES - LABOUR | E22: Excavation for foundations gang | F22: 1 plant operator (skill rate 2) - 66% of time | G22: 29.63
A23: 534 | B23: IMG_0072 | C23: CLASS E: EARTHWORKS | D23: RESOURCES - LABOUR | E23: Excavation for foundations gang | F23: 1 banksman (skill rate 4) | G23: 29.49
A24: 535 | B24: IMG_0072 | C24: CLASS E: EARTHWORKS | D24: RESOURCES - LABOUR | E24: Excavation for foundations gang | F24: Total Gang Rate/Hour | G24: 65.53
A25: 537 | B25: IMG_0072 | C25: CLASS E: EARTHWORKS | D25: RESOURCES - LABOUR | E25: General excavation gang | F25: 1 plant operator (skill rate 3) | G25: 38.96
A26: 538 | B26: IMG_0072 | C26: CLASS E: EARTHWORKS | D26: RESOURCES - LABOUR | E26: General excavation gang | F26: 1 plant operator (skill rate 3) - 25% of time | G26: 9.74
A27: 539 | B27: IMG_0072 | C27: CLASS E: EARTHWORKS | D27: RESOURCES - LABOUR | E27: General excavation gang | F27: 1 banksman (skill rate 4) | G27: 29.49
A28: 540 | B28: IMG_0072 | C28: CLASS E: EARTHWORKS | D28: RESOURCES - LABOUR | E28: General excavation gang | F28: Total Gang Rate/Hour | G28: 69.76
... A46: 565 | B46: IMG_0073 | C46: CLASS E: EARTHWORKS | D46: RESOURCES - LABOUR | E46: Horticultural works gang | F46: Total Gang Rate/Hour | G46: 49
A47: 568 | B47: IMG_0073 | C47: CLASS E: EARTHWORKS | D47: RESOURCES - PLANT | E47: Plant Resources Build-up Rate; Excavation for foundations | F47: hydraulic Backacter - 21 tonne (33% of time) | H47: 39
A48: 569 | B48: IMG_0073 | C48: CLASS E: EARTHWORKS | D48: RESOURCES - PLANT | E48: Plant Resources Build-up Rate; Excavation for foundations | F48: hydraulic Backacter - 14.5 tonne (33% of time) | H48: 32.18
A49: 570 | B49: IMG_0073 | C49: CLASS E: EARTHWORKS | D49: RESOURCES - PLANT | E49: Plant Resources Build-up Rate; Excavation for foundations | F49: 1000 kg hydraulic breaker (33% of time) | H49: 10.03
A50: 571 | B50: IMG_0073 | C50: CLASS E: EARTHWORKS | D50: RESOURCES - PLANT | E50: Plant Resources Build-up Rate; Excavation for foundations | F50: tractor loader - 0.80 m3 (33% of time) | H50: 26.11
A51: 572 | B51: IMG_0073 | C51: CLASS E: EARTHWORKS | D51: RESOURCES - PLANT | E51: Plant Resources Build-up Rate; Excavation for foundations | F51: Total Rate/Hour | H51: 107.32
A52: 574 | B52: IMG_0073 | C52: CLASS E: EARTHWORKS | D52: RESOURCES - PLANT | E52: Filling | F52: 1.5 m3 tractor loader | H52: 132.28
A53: 575 | B53: IMG_0073 | C53: CLASS E: EARTHWORKS | D53: RESOURCES - PLANT | E53: Filling | F53: 6t vibratory roller | H53: 50.62
A54: 576 | B54: IMG_0073 | C54: CLASS E: EARTHWORKS | D54: RESOURCES - PLANT | E54: Filling | F54: pedestrian Roller, Bomag BW35 | H54: 10.84
A55: 577 | B55: IMG_0073 | C55: CLASS E: EARTHWORKS | D55: RESOURCES - PLANT | E55: Filling | F55: Total Rate/Hour | H55: 193.74
A56: 579 | B56: IMG_0073 | C56: CLASS E: EARTHWORKS | D56: RESOURCES - PLANT | E56: Treatment of filled surfaces | F56: 1.5 m3 tractor loader | H56: 132.28
A57: 580 | B57: IMG_0073 | C57: CLASS E: EARTHWORKS | D57: RESOURCES - PLANT | E57: Treatment of filled surfaces | F57: pedestrian Roller, Bomag BW35 | H57: 10.84
A58: 581 | B58: IMG_0073 | C58: CLASS E: EARTHWORKS | D58: RESOURCES - PLANT | E58: Treatment of filled surfaces | F58: Total Rate/Hour | H58: 143.11
...

Sheet Preliminaries (Excluded)
A1: Preliminaries — CESMM Class A: General Items (EXCLUDED from the derivation)
A2: Excluded as requested. Retained here unchanged so they can be brought back in later — preliminaries are normally priced as a project-level allowance rather than built into unit rates.
A4: Ref | B4: Page | C4: Class | D4: Section | E4: Sub-heading | F4: Item | G4: Unit | H4: Gang hrs | I4: Labour £ | J4: Plant £ | K4: Material £ | L4: Published rate £
A5: 19 | B5: IMG_0065 | C5: CLASS A: GENERAL ITEMS | D5: 03 METHOD RELATED CHARGES | E5: Transport vehicles | F5: 4 WD utility short wheelbase | G5: week | J5: 1369.23 | L5: 1369.23
A6: 20 | B6: IMG_0065 | C6: CLASS A: GENERAL ITEMS | D6: 03 METHOD RELATED CHARGES | E6: Transport vehicles | F6: 4 WD long wheelbase | G6: week | J6: 1206.77 | L6: 1206.77
